Workbook

Sheet Read me
A1: Researched prices for approval
A2: What this is | B2: The 59 researched prices promoted into this review workbook. 'Your decision' is now prefilled from the checked recommendation; this completed review draft does not itself change the production rate card.
A3: How to use it | B3: Prices sheet: review or overwrite Approve, Reject or Hold in 'Your decision' (yellow, blue text). Band low and Band high are the approval range: the source's own 10th–90th percentile where supplied, otherwise the card's ±25%. The band must contain the researched price.
A4: Recommendation | B4: 28 approve, 12 hold, 19 reject. Approve: a published or measured business price. Hold: plausible, but a floor, single-source, reseller or promotion requiring validation. Reject: wholesale, consumer, introductory, mis-filed, wrong-product or untraceable.
A5: Effect of the recommendation, EUR/yr | B5: ='Sets'!E29 -> -26609012
A6: Effect if all are approved, EUR/yr | B6: ='Sets'!F29 -> -56688045
A7: Reading the effects | B7: EUR per year on the L0 baseline of the fifty companies. 'If approved alone' (Prices) is not additive: several prices can claim the same circuits. The Sets sheet approves each country and product together, and those totals do add.
A8: Why one price moves many circuits | B8: The estimate prices each circuit at the cheapest tier at or above what it needs. A researched rate that is cheaper than the seeded rates beneath it therefore prices every smaller circuit too - which is right if the bigger plan really is cheaper, and is why the effects are large.
A9: Decisions survive re-running research | B9: Fixed. promote used to delete each researched row and re-insert it unapproved, so every run_samples --repromote reset every approval and revocation - US DIA 10 Gbps and US MPLS 1 Gbps were approved on 13 October and lost that way. A decided row whose figure research finds again is now left as decided; a changed figure is proposed afresh, and its note names the decision it replaced.
A10: The verdicts recorded at promotion | B10: Fixed for future promotions. compare_to_benchmark compared the researched figure in its own currency with the seed's band in USD; 26 of these 59 carry a verdict made that way, and rows whose research a later run replaced keep the old wording. The USD columns here are converted at the card's own exchange rates.
A11: New Zealand | B11: No NZD exchange rate exists. Approving the NZD price would make every estimate with a New Zealand footprint refuse.
A12: How this was checked | B12: The pricing was rerun outside the route with nothing approved and reproduced all fifty stored L0 baselines to the cent. Every effect here comes from that same pricing with the price approved at the band shown.
A13: Completion status | B13: All 59 decisions are populated. Nine missing traceable source URLs were restored; three source URLs remain intentionally blank because the underlying prices are untraceable.
A14: Recommendation changes | B14: ES DIA 600, GB DIA 1 Gbps and GB DIA 10 Gbps changed from Reject to Hold: each is traceable, but each remains a reseller/carrier/aggregator floor requiring validation.
A15: Intentional gaps | B15: NZ BROADBAND_PON 100 keeps a blank USD conversion because the card has no NZD FX rate. GB MPLS 100, IT Ethernet 100 and NZ PON 100 keep blank source URLs because no traceable source was found.
A16: Audit trail | B16: See Review log for the controls and changes completed on 2026-10-25.

Sheet Review log
A1: Completion review log
A2: Audited and completed 2026-10-25. Decisions are a review draft and remain editable.
A4: Control | B4: Result | C4: Notes
A5: Researched price rows | B5: =COUNTA(Prices!A2:A60) -> 59 | C5: Expected: 59
A6: Decisions populated | B6: =COUNTA(Prices!G2:G60) -> 59 | C6: Expected: 59
A7: Approve decisions | B7: =COUNTIF(Prices!G2:G60,"Approve") -> 28 | C7: Published/measured business evidence
A8: Hold decisions | B8: =COUNTIF(Prices!G2:G60,"Hold") -> 12 | C8: Validation needed before promotion
A9: Reject decisions | B9: =COUNTIF(Prices!G2:G60,"Reject") -> 19 | C9: Not suitable for the rate card as filed
A10: Traceable source URLs | B10: =COUNTIF(Prices!T2:T60,"http*") -> 56 | C10: Three intentional untraceable gaps remain
A11: USD conversions present | B11: =COUNT(Prices!L2:L60) -> 58 | C11: NZD conversion intentionally blank
A13: Changes made
A14: Category | B14: Rows | C14: Change | D14: Rationale | E14: Source / reference | F14: Status
A15: Decision completion | B15: 2–60 | C15: Prefilled Your decision from the audited Recommendation | D15: Creates a complete, editable review draft. | F15: Complete
A16: Source repair | B16: 2, 14, 15, 30, 32, 33, 39, 44, 47 | C16: Restored direct source URLs and concise source wording | D16: Replaces orphaned run-narrative references with traceable pages. | E16: See Prices column T | F16: Complete
A17: Recommendation correction | B17: 44 | C17: Reject → Hold | D17: The €1,100 price is traceable; it remains a single reseller list price. | E17: Prices!T44 | F17: Complete
A18: Recommendation correction | B18: 50 | C18: Reject → Hold | D18: A traceable aggregator 'from' price fits the workbook's Hold definition. | E18: Prices!T50 | F18: Complete
A19: Recommendation correction | B19: 51 | C19: Reject → Hold | D19: A traceable carrier 'from' price fits the workbook's Hold definition. | E19: Prices!T51 | F19: Complete
A20: Provenance completion | B20: 11–13 | C20: Set Researched for to 'not recorded' | D20: The legacy promotion did not retain ownership; no case was invented. | F20: Documented gap
A21: Provenance completion | B21: 38 | C21: Set Researched for to anglo-american | D21: Inferred from ZA scope and the sole affected company; cell comment records the inference. | F21: Complete with caveat
A22: Intentional unresolved | B22: 55, 57, 59 | C22: Left Source URL blank | D22: The original evidence remains untraceable; Reject is maintained. | F22: Documented gap
A23: Intentional unresolved | B23: 59 | C23: Left USD conversion blank | D23: No NZD FX exists in the card; Reject is maintained. | F23: Documented gap
A24: Validation | B24: All | C24: Checked structure, duplicates, formulas, bands, FX consistency and dropdown | D24: No duplicate country/product/tier; all bands contain the researched price. | F24: Passed

Sheet Prices
A1: Price | B1: Country | C1: Product | D1: Tier (Mbps) | E1: Recommendation | F1: Why | G1: Your decision | H1: Band low | I1: Band high | J1: Researched price | K1: Currency | L1: Researched, USD/month | M1: Rate it replaces, USD/month | N1: Ratio | O1: Row it replaces | P1: Kind of price | Q1: Vendor / plan | R1: Source | S1: Source wording | T1: Source URL | U1: As of | V1: Researched for | W1: Effect if approved alone, EUR/yr | X1: Circuits re-priced | Y1: Largest effects | Z1: Approving it alone re-prices lower tiers | AA1: Verdict recorded at promotion
A2: AU-BROADBAND_HFC-250-researched | B2: AU | C2: BROADBAND_HFC | D2: 250 | E2: Approve | F2: Swoop's published standard business nbn 250/100 price of A$104/month. The introductory discount is excluded. | G2: Approve | H2: =J2*0.75 -> 78 | I2: =J2*1.25 -> 130 | J2: 104 | K2: AUD | L2: 70.27 | M2: 155 | N2: =IF(OR(L2="",M2=""),"",L2/M2) -> 0.45335484 | O2: SEED | P2: business retail | Q2: Swoop Business nbn 250/100 | R2: Swoop; COMPANY_PUBLISHED/FULL_PAGE | S2: 250/100 Mbps: standard A$104/month; introductory A$82/month for the first 6 months. | T2: https://www.swoop.com.au/business/nbn/ | U2: 2026-10 | V2: woolworths | W2: -1000837.4 | X2: 1130 | Y2: woolworths -1,000,837 | Z2: 100 Mbps at 115 > 250 Mbps at 70 | AA2: OUTSIDE_BAND - compared without converting currency
A3: AU-BROADBAND_HFC-2000-researched | B3: AU | C3: BROADBAND_HFC | D3: 2000 | E3: Approve | F3: Aussie Broadband business Hyperfast 2000, published; a trade guide puts business fibre plans at A$100-220. | G3: Approve | H3: =J3*0.75 -> 165 | I3: =J3*1.25 -> 275 | J3: 220 | K3: AUD | L3: 148.65 | N3: =IF(OR(L3="",M3=""),"",L3/M3) | O3: none - new tier | P3: business retail | Q3: BROADBAND_HFC AU 2000Mbps MRC (Aussie Broadband Business Hyperfast HFC) | R3: Aussie Broadband / WhistleOut; AGGREGATOR/SNIPPET_ONLY | S3: Aussie Broadband FTTP Business Hyperfast Plus 2000/500 Unlimited Data $220/mth | T3: https://www.whistleout.com.au/Broadband/Guides/NBN-business-plans-compared | U3: 2026 | V3: woolworths | W3: -75022.899 | X3: 1130 | Y3: woolworths -75,023 | Z3: 1000 Mbps at 250 > 2000 Mbps at 149 | AA3: NO_BENCHMARK_AT_BANDWIDTH - compared without converting currency
A4: AU-BROADBAND_PON-250-researched | B4: AU | C4: BROADBAND_PON | D4: 250 | E4: Approve | F4: Aussie Broadband business FTTP 250/100, published by the provider and confirmed by an aggregator. | G4: Approve | H4: =J4*0.75 -> 85.5 | I4: =J4*1.25 -> 142.5 | J4: 114 | K4: AUD | L4: 77.03 | M4: 101 | N4: =IF(OR(L4="",M4=""),"",L4/M4) -> 0.76267327 | O4: SEED | P4: business retail | Q4: BROADBAND_PON AU 250Mbps MRC (Aussie Broadband Business FTTP 250/100) | R4: Aussie Broadband Enterprise; COMPANY_PUBLISHED/SNIPPET_ONLY | S4: Superfast Plus 250/100 $114/month | T4: https://www.aussiebroadband.com.au/enterprise/internet/nbn-plans/ | U4: 2026 | V4: woolworths | W4: 0 | X4: 0 | Z4: no | AA4: WITHIN_BAND - compared without converting currency
A5: AU-ETHERNET-250-researched | B5: AU | C5: ETHERNET | D5: 250 | E5: Approve | F5: NBN Enterprise Ethernet retail, ex GST, 36-month: Swoop and Vocus publish the same A$399. | G5: Approve | H5: =J5*0.75 -> 299.25 | I5: =J5*1.25 -> 498.75 | J5: 399 | K5: AUD | L5: 269.59 | N5: =IF(OR(L5="",M5=""),"",L5/M5) | O5: none - new tier | P5: business retail | Q5: ETHERNET AU 250Mbps MRC (NBN Enterprise Ethernet retail, ex GST) | R5: Swoop; COMPANY_PUBLISHED/SNIPPET_ONLY | S5: Business Fibre 250/250 Mbps $399 per month | T5: https://www.swoop.com.au/business/enterprise-ethernet/ | U5: 2026 | V5: woolworths | W5: -53227.977 | X5: 5 | Y5: woolworths -53,228 | Z5: no | AA5: NO_BENCHMARK_AT_BANDWIDTH - compared without converting currency
A6: AU-ETHERNET-500-researched | B6: AU | C6: ETHERNET | D6: 500 | E6: Approve | F6: NBN Enterprise Ethernet retail, ex GST, 36-month: Vocus A$469, Swoop A$499. | G6: Approve | H6: =J6*0.75 -> 351.75 | I6: =J6*1.25 -> 586.25 | J6: 469 | K6: AUD | L6: 316.89 | M6: 1288 | N6: =IF(OR(L6="",M6=""),"",L6/M6) -> 0.24603261 | O6: SEED | P6: business retail | Q6: ETHERNET AU 500Mbps MRC (NBN Enterprise Ethernet retail, ex GST) | R6: Vocus; COMPANY_PUBLISHED/SNIPPET_ONLY | S6: 500/500Mbps Starting at $469 / per month (ex. GST) | T6: https://www.vocus.com.au/enterprise/internet-and-networks/nbn-enterprise-ethernet | U6: 2026 | V6: woolworths | W6: -50755.936 | X6: 5 | Y6: woolworths -50,756 | Z6: no | AA6: OUTSIDE_BAND - compared without converting currency
A7: AU-ETHERNET-1000-researched | B7: AU | C7: ETHERNET | D7: 1000 | E7: Approve | F7: NBN Enterprise Ethernet retail, ex GST, 36-month: Swoop and Vocus A$699, Telstra via Telair A$659. | G7: Approve | H7: =J7*0.75 -> 524.25 | I7: =J7*1.25 -> 873.75 | J7: 699 | K7: AUD | L7: 472.3 | M7: 1450 | N7: =IF(OR(L7="",M7=""),"",L7/M7) -> 0.32572414 | O7: SEED | P7: business retail | Q7: ETHERNET AU 1000Mbps MRC (NBN Enterprise Ethernet retail, ex GST) | R7: Swoop; COMPANY_PUBLISHED/SNIPPET_ONLY | S7: Business Fibre 1000/1000 Mbps $699 per month | T7: https://www.swoop.com.au/business/enterprise-ethernet/ | U7: 2026 | V7: woolworths | W7: -347193.15 | X7: 25 | Y7: rio-tinto -304,560; woolworths -42,634 | Z7: 500 Mbps at 1288 > 1000 Mbps at 472 | AA7: OUTSIDE_BAND - compared without converting currency
A8: BE-BROADBAND_PON-150-researched | B8: BE | C8: BROADBAND_PON | D8: 150 | E8: Approve | F8: Proximus Business Go Fiber 150, the standard price after the 12-month promotion, ex VAT, read from the full page. | G8: Approve | H8: =J8*0.75 -> 45 | I8: =J8*1.25 -> 75 | J8: 60 | K8: EUR | L8: 68.88 | N8: =IF(OR(L8="",M8=""),"",L8/M8) | O8: none - new tier | P8: business retail | Q8: BROADBAND_PON 150 Mbps MRC (business shared fibre, Proximus Go Fiber) | R8: Proximus (proximus.be); COMPANY_PUBLISHED/FULL_PAGE | S8: Business Internet Go Fiber 150 Mbps: €45/month during 12 months, then €60/month | T8: https://www.proximus.be/en/business/internet-subscription | U8: 2025 | V8: bnp-paribas | W8: 0 | X8: 0 | Z8: no | AA8: NO_BENCHMARK_AT_BANDWIDTH - compared without converting currency
A9: FR-DIA-1000-researched | B9: FR | C9: DIA | D9: 1000 | E9: Approve | F9: Orange Business FTTO 1 Gbps, approximately EUR 1,200 per a trade-press snippet. It sits close to the seed (0.91x). | G9: Approve | H9: =J9*0.75 -> 900 | I9: =J9*1.25 -> 1500 | J9: 1200 | K9: EUR | L9: 1377.57 | M9: 1520 | N9: =IF(OR(L9="",M9=""),"",L9/M9) -> 0.90629605 | O9: SEED | P9: business retail indicative | Q9: DIA 1000 Mbps MRC France (Orange Business FTTO dedicated fibre) | R9: myadsl.fr; TRADE_PRESS/SNIPPET_ONLY | S9: Offre intermédiaire: 1 Gb/s, SLA amélioré, support 24/7 – tarif mensuel approximatif: 1 200 € | T9: https://www.myadsl.fr/cout-ftto-orange-2025/ | U9: 2025 | V9: bnp-paribas | W9: -106959.98 | X9: 72 | Y9: bnp-paribas -29,777; siemens -26,800; capgemini -14,889 | Z9: 500 Mbps at 1398 > 1000 Mbps at 1378 | AA9: WITHIN_BAND - compared without converting currency
A10: GB-BROADBAND_HFC-200-researched | B10: GB | C10: BROADBAND_HFC | D10: 200 | E10: Approve | F10: Virgin Media Business Voom 200, published, ex VAT, 24-month. | G10: Approve | H10: =J10*0.75 -> 22.4625 | I10: =J10*1.25 -> 37.4375 | J10: 29.95 | K10: GBP | L10: 40.13 | N10: =IF(OR(L10="",M10=""),"",L10/M10) | O10: none - new tier | P10: business retail | Q10: BROADBAND_HFC 200Mbps MRC (Virgin Media Business Voom 200) | R10: virginmediabusiness.co.uk; COMPANY_PUBLISHED/SNIPPET_ONLY | S10: Prices start from just £29.95 per month | T10: https://www.virginmediabusiness.co.uk/connectivity/internet-access/business-broadband/ | U10: 2026 | V10: boots | W10: -4265183 | X10: 5864 | Y10: tesco -2,729,944; boots -1,535,239 | Z10: 100 Mbps at 80 > 200 Mbps at 40 | AA10: NO_BENCHMARK_AT_BANDWIDTH - compared without converting currency
A11: GB-BROADBAND_HFC-400-researched | B11: GB | C11: BROADBAND_HFC | D11: 400 | E11: Approve | F11: Virgin Media Business Voom 400, published, ex VAT, 24-month. | G11: Approve | H11: =J11*0.75 -> 26.2125 | I11: =J11*1.25 -> 43.6875 | J11: 34.95 | K11: GBP | L11: 46.83 | N11: =IF(OR(L11="",M11=""),"",L11/M11) | O11: none - new tier | P11: business retail | Q11: BROADBAND_HFC 400Mbps MRC — Virgin Media Business Voom 400 | R11: virginmediabusiness.co.uk; COMPANY_PUBLISHED/SNIPPET_ONLY | S11: Voom 400 | Download 400Mbps | £34.95 per month | T11: https://www.virginmediabusiness.co.uk/connectivity/internet-access/business-broadband/ | U11: 2026 | V11: not recorded | W11: -5784801.3 | X11: 7780 | Y11: tesco -2,460,455; mcdonalds -1,526,396; boots -1,383,686 | Z11: 250 Mbps at 108 > 400 Mbps at 47 | AA11: NO_BENCHMARK_AT_BANDWIDTH - compared without converting currency
A12: GB-BROADBAND_HFC-600-researched | B12: GB | C12: BROADBAND_HFC | D12: 600 | E12: Approve | F12: Virgin Media Business Voom 600, published, ex VAT, 24-month. | G12: Approve | H12: =J12*0.75 -> 29.2125 | I12: =J12*1.25 -> 48.6875 | J12: 38.95 | K12: GBP | L12: 52.19 | N12: =IF(OR(L12="",M12=""),"",L12/M12) | O12: none - new tier | P12: business retail | Q12: BROADBAND_HFC 600Mbps MRC — Virgin Media Business Voom 600 | R12: virginmediabusiness.co.uk; COMPANY_PUBLISHED/SNIPPET_ONLY | S12: Voom 600 | Download 600Mbps | £38.95 per month | T12: https://www.virginmediabusiness.co.uk/connectivity/internet-access/business-broadband/ | U12: 2026 | V12: not recorded | W12: -5336326.9 | X12: 7780 | Y12: tesco -2,244,864; mcdonalds -1,438,586; boots -1,262,444 | Z12: 500 Mbps at 140 > 600 Mbps at 52 | AA12: NO_BENCHMARK_AT_BANDWIDTH - compared without converting currency
A13: GB-BROADBAND_HFC-1000-researched | B13: GB | C13: BROADBAND_HFC | D13: 1000 | E13: Approve | F13: Virgin Media Business Voom Gig1, published, ex VAT, 24-month. | G13: Approve | H13: =J13*0.75 -> 32.9625 | I13: =J13*1.25 -> 54.9375 | J13: 43.95 | K13: GBP | L13: 58.89 | M13: 176 | N13: =IF(OR(L13="",M13=""),"",L13/M13) -> 0.33460227 | O13: SEED | P13: business retail | Q13: BROADBAND_HFC 1000Mbps MRC — Virgin Media Business Voom Gig1 | R13: virginmediabusiness.co.uk; COMPANY_PUBLISHED/SNIPPET_ONLY | S13: Voom Gig1 | Download 1000Mbps | £43.95 per month | T13: https://www.virginmediabusiness.co.uk/connectivity/internet-access/business-broadband/ | U13: 2026 | V13: not recorded | W13: -4775734 | X13: 7780 | Y13: tesco -1,975,375; mcdonalds -1,328,824; boots -1,110,892 | Z13: 500 Mbps at 140 > 1000 Mbps at 59 | AA13: OUTSIDE_BAND - compared without converting currency
A14: GB-BROADBAND_HFC-2000-researched | B14: GB | C14: BROADBAND_HFC | D14: 2000 | E14: Approve | F14: Virgin Media Business Voom Gig2, published, ex VAT, 24-month. | G14: Approve | H14: =J14*0.75 -> 62.9625 | I14: =J14*1.25 -> 104.9375 | J14: 83.95 | K14: GBP | L14: 112.49 | N14: =IF(OR(L14="",M14=""),"",L14/M14) | O14: none - new tier | P14: business retail | Q14: Virgin Media Business Voom Gig2 | R14: Virgin Media Business; COMPANY_PUBLISHED/FULL_PAGE | S14: Voom Gig2: 2,000 Mbps download / 200 Mbps upload, £83.95/month, 24-month contract, ex VAT. | T14: https://www.virginmediabusiness.co.uk/connectivity/internet-access/business-broadband/ | U14: 2026-10 | V14: royal-mail | W14: -573054.49 | X14: 1916 | Y14: mcdonalds -450,727; deutsche-post-dhl -103,186; royal-mail -13,459 | Z14: 1000 Mbps at 176 > 2000 Mbps at 112 | AA14: NO_BENCHMARK_AT_BANDWIDTH - compared without converting currency
A15: GB-BROADBAND_PON-100-researched | B15: GB | C15: BROADBAND_PON | D15: 100 | E15: Approve | F15: BT Business Full Fibre 100 at GBP 35 a month ex VAT, published (verified May 2026). | G15: Approve | H15: =J15*0.75 -> 26.25 | I15: =J15*1.25 -> 43.75 | J15: 35 | K15: GBP | L15: 46.9 | M15: 70 | N15: =IF(OR(L15="",M15=""),"",L15/M15) -> 0.67 | O15: SEED | P15: business retail | Q15: BT Business Full Fibre 100 | R15: BT Business; COMPANY_PUBLISHED/FULL_PAGE | S15: Full Fibre 100 recorded at £35/month ex VAT in May 2026; current offers are address- and promotion-dependent. | T15: https://business.bt.com/products/broadband-and-internet/deals/ | U15: 2026-05 | V15: saint-gobain | W15: -742283.22 | X15: 2847 | Y15: iberdrola -243,421; network-rail -216,375; nhs-england -161,315 | Z15: 50 Mbps at 58 > 100 Mbps at 47 | AA15: WITHIN_BAND - compared without converting currency
A16: NL-DIA-200-researched | B16: NL | C16: DIA | D16: 200 | E16: Approve | F16: Eurofiber DIA 200 from about EUR 348, as quoted by a broker; a carrier's indicative business price. No circuit in the set uses it. | G16: Approve | H16: =J16*0.75 -> 261 | I16: =J16*1.25 -> 435 | J16: 348 | K16: EUR | L16: 399.49 | N16: =IF(OR(L16="",M16=""),"",L16/M16) | O16: none - new tier | P16: business retail indicative | Q16: DIA MRC 200 Mbps (NL, Eurofiber) | R16: Connected Networks; COMPANY_PUBLISHED/FULL_PAGE | S16: DIA pricing via Eurofiber starts from approximately €348/month for 200Mbps. | T16: https://www.connectednetworks.io/countries/holland-the-netherlands-business-internet-connectivity | U16: 2025 | V16: ahold-delhaize | W16: 0 | X16: 0 | Z16: 100 Mbps at 500 > 200 Mbps at 399 | AA16: NO_BENCHMARK_AT_BANDWIDTH - compared without converting currency
A17: SG-BROADBAND_PON-500-researched | B17: SG | C17: BROADBAND_PON | D17: 500 | E17: Approve | F17: Business dynamic fibre on a 24-month contract: StarHub S$109, Singtel S$118. | G17: Approve | H17: =J17*0.75 -> 81.75 | I17: =J17*1.25 -> 136.25 | J17: 109 | K17: SGD | L17: 85.16 | M17: 115 | N17: =IF(OR(L17="",M17=""),"",L17/M17) -> 0.74052174 | O17: SEED | P17: business retail | Q17: BROADBAND_PON 500 Mbps MRC business dynamic — Singapore (Singtel) | R17: DollarsAndSense.sg; AGGREGATOR/SNIPPET_ONLY | S17: Singtel · $118 · $178 [for 500Mbps and 1Gbps dynamic broadband, 24-month contract] | T17: https://dollarsandsense.sg/price-guide-to-business-broadband-plans-for-offices-in-singapore/ | U17: 2025 | V17: dbs | W17: -2199.0919 | X17: 36 | Y17: dbs -2,199 | Z17: 250 Mbps at 91 > 500 Mbps at 85 | AA17: WITHIN_BAND - compared without converting currency
A18: SG-BROADBAND_PON-1000-researched | B18: SG | C18: BROADBAND_PON | D18: 1000 | E18: Approve | F18: Business dynamic fibre on a 24-month contract: Singtel S$178, StarHub S$174. | G18: Approve | H18: =J18*0.75 -> 133.5 | I18: =J18*1.25 -> 222.5 | J18: 178 | K18: SGD | L18: 139.06 | M18: 149 | N18: =IF(OR(L18="",M18=""),"",L18/M18) -> 0.93328859 | O18: SEED | P18: business retail | Q18: BROADBAND_PON 1000 Mbps MRC business dynamic — Singapore (Singtel) | R18: DollarsAndSense.sg; AGGREGATOR/SNIPPET_ONLY | S18: Singtel · $118 · $178 [for 500Mbps and 1Gbps dynamic broadband, 24-month contract] | T18: https://dollarsandsense.sg/price-guide-to-business-broadband-plans-for-offices-in-singapore/ | U18: 2025 | V18: dbs | W18: -320.98946 | X18: 3 | Y18: novartis -321 | Z18: no | AA18: WITHIN_BAND - compared without converting currency
A19: SG-DIA-10000-researched | B19: SG | C19: DIA | D19: 10000 | E19: Approve | F19: TeleGeography's survey-based 10 GigE DIA benchmark for Singapore. No circuit in the set uses it. | G19: Approve | H19: =J19*0.75 -> 3375 | I19: =J19*1.25 -> 5625 | J19: 4500 | K19: USD | L19: 4500 | N19: =IF(OR(L19="",M19=""),"",L19/M19) | O19: none - new tier | P19: survey benchmark | Q19: DIA 10000 Mbps (10 GigE) MRC — SG (TeleGeography 2026) | R19: TeleGeography; TRADE_PRESS/SNIPPET_ONLY | S19: $4,500 for 10 GigE | T19: https://resources.telegeography.com/dia-pricing-in-asia-and-oceania | U19: 2026 | V19: maersk | W19: 0 | X19: 0 | Z19: no | AA19: NO_BENCHMARK_AT_BANDWIDTH
A20: US-BROADBAND_HFC-100-researched | B20: US | C20: BROADBAND_HFC | D20: 100 | E20: Approve | F20: Lightyear transaction dataset, median of US business broadband at 100 Mbps; the band is its 10th-90th percentile. | G20: Approve | H20: 60 | I20: 175 | J20: 100 | K20: USD | L20: 100 | M20: 120 | N20: =IF(OR(L20="",M20=""),"",L20/M20) -> 0.83333333 | O20: SEED | P20: market median | Q20: BROADBAND_HFC 100 Mbps MRC median | R20: Lightyear; AGGREGATOR/FULL_PAGE | S20: 100 Mbps | $60 | $100 | $175 | T20: https://lightyear.ai/resources/dedicated-internet-access-dia-ultimate-pricing-guide | U20: 2025-2026 | V20: ahold-delhaize | W20: -6522.7981 | X20: 30 | Y20: maersk -3,696; ahold-delhaize -2,174; fresenius -435 | Z20: no | AA20: WITHIN_BAND
A21: US-BROADBAND_HFC-500-researched | B21: US | C21: BROADBAND_HFC | D21: 500 | E21: Approve | F21: Lightyear transaction dataset, median at 500 Mbps; the band is its 10th-90th percentile. | G21: Approve | H21: 65 | I21: 212 | J21: 110 | K21: USD | L21: 110 | M21: 208 | N21: =IF(OR(L21="",M21=""),"",L21/M21) -> 0.52884615 | O21: SEED | P21: market median | Q21: BROADBAND_HFC/PON 500 Mbps MRC median | R21: Lightyear; AGGREGATOR/FULL_PAGE | S21: 500 Mbps | $65 | $110 | $212 | T21: https://lightyear.ai/resources/dedicated-internet-access-dia-ultimate-pricing-guide | U21: 2025-2026 | V21: ahold-delhaize | W21: -17454374 | X21: 17371 | Y21: mcdonalds -14,602,237; ahold-delhaize -1,096,373; ups -865,097 | Z21: 250 Mbps at 162 > 500 Mbps at 110 | AA21: OUTSIDE_BAND
A22: US-BROADBAND_HFC-1000-researched | B22: US | C22: BROADBAND_HFC | D22: 1000 | E22: Approve | F22: Lightyear transaction dataset, median at 1 Gbps; the band is its 10th-90th percentile. | G22: Approve | H22: 124 | I22: 330 | J22: 184 | K22: USD | L22: 184 | M22: 264 | N22: =IF(OR(L22="",M22=""),"",L22/M22) -> 0.6969697 | O22: SEED | P22: market median | Q22: BROADBAND_HFC/PON 1 Gbps MRC median | R22: Lightyear; AGGREGATOR/FULL_PAGE | S22: 1 Gbps | $124 | $184 | $330 | T22: https://lightyear.ai/resources/dedicated-internet-access-dia-ultimate-pricing-guide | U22: 2025-2026 | V22: ahold-delhaize | W22: -4006040.9 | X22: 15354 | Y22: mcdonalds -3,576,058; ups -211,860; victorias-secret -208,729 | Z22: 500 Mbps at 208 > 1000 Mbps at 184 | AA22: OUTSIDE_BAND
A23: US-BROADBAND_PON-100-researched | B23: US | C23: BROADBAND_PON | D23: 100 | E23: Approve | F23: Lightyear transaction dataset, median at 100 Mbps (HFC and PON together); the band is its 10th-90th percentile. | G23: Approve | H23: 60 | I23: 175 | J23: 100 | K23: USD | L23: 100 | M23: 85 | N23: =IF(OR(L23="",M23=""),"",L23/M23) -> 1.1764706 | O23: SEED | P23: market median | Q23: BROADBAND_PON/HFC 100 Mbps MRC – US business | R23: Lightyear; AGGREGATOR/SNIPPET_ONLY | S23: 100 Mbps | $60 | $100 | $175 — Last 12 Months Broadband Pricing ($MRC) by Bandwidth Tier | T23: https://lightyear.ai/resources/dedicated-internet-access-dia-ultimate-pricing-guide | U23: 2025-2026 | V23: volkswagen | W23: 290896.36 | X23: 1770 | Y23: toyota +1,756; danone +2,107; bayer +3,512 | Z23: no | AA23: WITHIN_BAND
A24: US-BROADBAND_PON-500-researched | B24: US | C24: BROADBAND_PON | D24: 500 | E24: Approve | F24: Verizon Fios Business 500 at $99, consistent with the Lightyear 500 Mbps median of $110. | G24: Approve | H24: =J24*0.75 -> 74.25 | I24: =J24*1.25 -> 123.75 | J24: 99 | K24: USD | L24: 99 | M24: 145 | N24: =IF(OR(L24="",M24=""),"",L24/M24) -> 0.68275862 | O24: SEED | P24: business retail | Q24: BROADBAND_PON 500 Mbps MRC – US, Verizon Fios Business | R24: highspeedinternet.com (Verizon published tariff); AGGREGATOR/SNIPPET_ONLY | S24: Verizon Business Fios 500 | $99/mo. | Up to 500Mbps | Fiber | T24: https://www.highspeedinternet.com/resources/business-internet-guide | U24: 2026 | V24: bayer | W24: -77962.367 | X24: 243 | Y24: simmons-bank -20,511; basf -13,372; siemens -11,391 | Z24: 250 Mbps at 114 > 500 Mbps at 99 | AA24: OUTSIDE_BAND
A25: US-DIA-100-researched | B25: US | C25: DIA | D25: 100 | E25: Approve | F25: Lightyear 36-month DIA median at 100 Mbps; the band is its 10th-90th percentile. | G25: Approve | H25: 333 | I25: 641 | J25: 492 | K25: USD | L25: 492 | M25: 480 | N25: =IF(OR(L25="",M25=""),"",L25/M25) -> 1.025 | O25: SEED | P25: market median | Q25: DIA 100 Mbps MRC – US (Lightyear dataset, 36-month, median) | R25: Lightyear.ai; AGGREGATOR/SNIPPET_ONLY | S25: Median DIA MRC 36-month: 100 Mbps $492, 1 Gbps $901, 10 Gbps $1,987 (US, mixed geo/ISP) | T25: https://lightyear.ai/resources/dedicated-internet-access-dia-ultimate-pricing-guide | U25: 2025-2026 | V25: abb | W25: 418650.66 | X25: 2670 | Y25: victorias-secret +314; ahold-delhaize +3,920; maersk +6,272 | Z25: no | AA25: WITHIN_BAND
A26: US-DIA-1000-researched | B26: US | C26: DIA | D26: 1000 | E26: Approve | F26: Lightyear 36-month DIA median at 1 Gbps; the band is its 10th-90th percentile. | G26: Approve | H26: 600 | I26: 1312 | J26: 901 | K26: USD | L26: 901 | M26: 1350 | N26: =IF(OR(L26="",M26=""),"",L26/M26) -> 0.66740741 | O26: SEED | P26: market median | Q26: DIA 1000 Mbps MRC – US (Lightyear dataset, 36-month, median) | R26: Lightyear.ai; AGGREGATOR/SNIPPET_ONLY | S26: Median DIA 1 Gbps $901/month (US, 36-month, 10th pct $600, 90th pct $1,312) | T26: https://lightyear.ai/resources/dedicated-internet-access-dia-ultimate-pricing-guide | U26: 2025-2026 | V26: abb | W26: -1331147.1 | X26: 399 | Y26: simmons-bank -537,948; siemens -314,464; nestle -84,483 | Z26: 500 Mbps at 1242 > 1000 Mbps at 901 | AA26: OUTSIDE_BAND
A27: US-DIA-10000-researched | B27: US | C27: DIA | D27: 10000 | E27: Approve | F27: Lightyear 36-month DIA median at 10 Gbps; the band is its 10th-90th percentile. Approved on 13 Oct, and lost to a re-promotion. | G27: Approve | H27: 1175 | I27: 2853 | J27: 1987 | K27: USD | L27: 1987 | N27: =IF(OR(L27="",M27=""),"",L27/M27) | O27: none - new tier | P27: market median | Q27: DIA 10000 Mbps MRC – US (Lightyear dataset, 36-month, median) | R27: Lightyear.ai; AGGREGATOR/SNIPPET_ONLY | S27: Median DIA 10 Gbps $1,987/month (US, 36-month, 10th pct $1,175, 90th pct $2,853) | T27: https://lightyear.ai/resources/dedicated-internet-access-dia-ultimate-pricing-guide | U27: 2025-2026 | V27: abb | W27: 0 | X27: 0 | Z27: no | AA27: NO_BENCHMARK_AT_BANDWIDTH
A28: US-ETHERNET-10000-researched | B28: US | C28: ETHERNET | D28: 10000 | E28: Approve | F28: Lightyear Ethernet private-line median at 10 Gbps; the band is its 10th-90th percentile. | G28: Approve | H28: 1244 | I28: 2157 | J28: 1807 | K28: USD | L28: 1807 | M28: 3450 | N28: =IF(OR(L28="",M28=""),"",L28/M28) -> 0.52376812 | O28: SEED | P28: market median | Q28: ETHERNET 10000 Mbps point-to-point MRC – US (Lightyear dataset) | R28: lightyear.ai (Ethernet Private Line guide); TRADE_PRESS/SNIPPET_ONLY | S28: 10 Gbps Point-to-Point (Ethernet): 10th pct $1,244, Median $1,807, 90th pct $2,157 | T28: https://lightyear.ai/blogs/ethernet-private-line-cost | U28: 2025-2026 | V28: simmons-bank | W28: -32322.017 | X28: 2 | Y28: shell -32,322 | Z28: 9000 Mbps at 3267 > 10000 Mbps at 1807 | AA28: OUTSIDE_BAND
A29: US-MPLS-1000-researched | B29: US | C29: MPLS | D29: 1000 | E29: Approve | F29: Lightyear median for an all-inclusive managed MPLS service at 1 Gbps. Approved on 13 Oct, and lost to a re-promotion. | G29: Approve | H29: =J29*0.75 -> 1079.25 | I29: =J29*1.25 -> 1798.75 | J29: 1439 | K29: USD | L29: 1439 | N29: =IF(OR(L29="",M29=""),"",L29/M29) | O29: none - new tier | P29: market median | Q29: MPLS 1000Mbps MRC | R29: Lightyear; AGGREGATOR/SNIPPET_ONLY | S29: MPLS | $1,439 | $17,268 | All-inclusive managed service (1 Gbps) | T29: https://lightyear.ai/blogs/sd-wan-vs-mpls-cost-comparison | U29: 2026 | V29: toyota | W29: 0 | X29: 0 | Z29: no | AA29: NO_BENCHMARK_AT_BANDWIDTH
A30: AU-DIA-250-researched | B30: AU | C30: DIA | D30: 250 | E30: Hold | F30: Vocus publishes Fast Fibre from A$339/month ex GST. Hold because it is a floor and the same research cites materially higher enterprise dedicated-fibre ranges. | G30: Hold | H30: =J30*0.75 -> 254.25 | I30: =J30*1.25 -> 423.75 | J30: 339 | K30: AUD | L30: 229.05 | N30: =IF(OR(L30="",M30=""),"",L30/M30) | O30: none - new tier | P30: business retail floor | Q30: Vocus Fast Fibre (250 Mbps+) | R30: Vocus; COMPANY_PUBLISHED/FULL_PAGE | S30: Fast Fibre from A$339/month ex GST; dedicated, symmetric and 1:1 contention. | T30: https://www.vocus.com.au/enterprise/internet-and-networks | U30: 2026-10 | V30: woolworths | W30: -459004.96 | X30: 30 | Y30: woolworths -459,005 | Z30: no | AA30: NO_BENCHMARK_AT_BANDWIDTH - compared without converting currency
A31: BE-BROADBAND_PON-2500-researched | B31: BE | C31: BROADBAND_PON | D31: 2500 | E31: Hold | F31: Proximus Flex+ is a small-business pack 'from' EUR 95 with services bundled in, not a connectivity price. No circuit in the set uses it. | G31: Hold | H31: =J31*0.75 -> 71.25 | I31: =J31*1.25 -> 118.75 | J31: 95 | K31: EUR | L31: 109.06 | N31: =IF(OR(L31="",M31=""),"",L31/M31) | O31: none - new tier | P31: bundle | Q31: BROADBAND_PON 2500 Mbps MRC (Proximus Flex+ Giga Fiber 2.5 Gbps) | R31: Proximus (proximus.com press release Jul 2025); COMPANY_PUBLISHED/FULL_PAGE | S31: Business Flex+ Giga Fiber 2.5 Gbps symmetric: from €95/month | T31: https://www.proximus.com/news/2025/202507-business-flex-plus-packs-as-of-july-1-2025.html | U31: 2025-07 | V31: bnp-paribas | W31: 0 | X31: 0 | Z31: 1000 Mbps at 136 > 2500 Mbps at 109 | AA31: NO_BENCHMARK_AT_BANDWIDTH - compared without converting currency
A32: ES-DIA-100-researched | B32: ES | C32: DIA | D32: 100 | E32: Hold | F32: Direct Telecom publishes a 100/100 Mbps guaranteed circuit at €159.99/month. Hold because it is a single reseller list price and has a large model effect. | G32: Hold | H32: =J32*0.75 -> 119.9925 | I32: =J32*1.25 -> 199.9875 | J32: 159.99 | K32: EUR | L32: 183.66 | N32: =IF(OR(L32="",M32=""),"",L32/M32) | O32: none - new tier | P32: reseller list | Q32: Direct Telecom Business Class Fibre — 100/100 Guaranteed | R32: Direct Telecom; COMPANY_PUBLISHED/FULL_PAGE | S32: 100/100 Mbps guaranteed circuit: €159.99/month. | T32: https://direct-telecom.es/internet/business_class_fibre/ | U32: 2026-10 | V32: inditex | W32: -19536535 | X32: 2072 | Y32: santander -14,590,860; fresenius -4,811,403; carrefour -134,272 | Z32: no | AA32: NO_BENCHMARK_AT_BANDWIDTH - compared without converting currency
A33: ES-DIA-1000-researched | B33: ES | C33: DIA | D33: 1000 | E33: Hold | F33: Direct Telecom publishes a 1,000/1,000 Mbps dedicated circuit at €449/month. Hold because it is a single reseller list price and reprices lower Spanish DIA tiers. | G33: Hold | H33: =J33*0.75 -> 336.75 | I33: =J33*1.25 -> 561.25 | J33: 449 | K33: EUR | L33: 515.44 | M33: 1300 | N33: =IF(OR(L33="",M33=""),"",L33/M33) -> 0.39649231 | O33: SEED | P33: reseller list | Q33: Direct Telecom Business Class Fibre — 1 Gbps Dedicated (1Net) | R33: Direct Telecom; COMPANY_PUBLISHED/FULL_PAGE | S33: 1,000/1,000 Mbps dedicated circuit (1Net): €449/month. | T33: https://direct-telecom.es/internet/business_class_fibre/ | U33: 2026-10 | V33: inditex | W33: -12196996 | X33: 2100 | Y33: santander -8,937,825; fresenius -2,947,289; iberdrola -164,023 | Z33: 500 Mbps at 1196 > 1000 Mbps at 515 | AA33: OUTSIDE_BAND - compared without converting currency
A34: GB-DIA-100-researched | B34: GB | C34: DIA | D34: 100 | E34: Hold | F34: Virgin's 'packages start at' floor. The seed it would replace is survey-sourced (grade C) and sits inside the GBP 175-320 range the same research quotes. | G34: Hold | H34: =J34*0.75 -> 138.75 | I34: =J34*1.25 -> 231.25 | J34: 185 | K34: GBP | L34: 247.89 | M34: 335 | N34: =IF(OR(L34="",M34=""),"",L34/M34) -> 0.73997015 | O34: SEED | P34: business retail floor | Q34: GB DIA 100 Mbps MRC – Virgin Media Business published tariff | R34: Virgin Media Business; COMPANY_PUBLISHED/SNIPPET_ONLY | S34: Our packages start at £185 per month which provided 100Mbps upload and download speeds. | T34: https://www.virginmediabusiness.co.uk/connectivity/internet-access/leased-lines-for-business/ | U34: 2025 | V34: unilever | W34: -2414090.9 | X34: 2429 | Y34: nhs-england -1,121,155; saint-gobain -796,760; santander -280,459 | Z34: no | AA34: OUTSIDE_BAND - compared without converting currency
A35: GB-DIA-500-researched | B35: GB | C35: DIA | D35: 500 | E35: Hold | F35: Vodafone 'from' GBP 257 on a 60-month term. The same research puts urban 500 Mbps at GBP 350-500 on 36 months. | G35: Hold | H35: =J35*0.75 -> 192.75 | I35: =J35*1.25 -> 321.25 | J35: 257 | K35: GBP | L35: 344.37 | M35: 690 | N35: =IF(OR(L35="",M35=""),"",L35/M35) -> 0.49908696 | O35: SEED | P35: business retail floor | Q35: DIA 500Mbps MRC – Vodafone Business published retail tariff | R35: Vodafone Business; COMPANY_PUBLISHED/FULL_PAGE | S35: Vodafone Dedicated Internet Access (Managed) 500 Mbps Monthly price from £257 (ex. VAT) 60 months | T35: https://www.vodafone.co.uk/business/connectivity/data-connectivity/dedicated-internet-access | U35: 2025 | V35: nhs-england | W35: -2330376.1 | X35: 520 | Y35: deutsche-post-dhl -1,892,302; royal-mail -272,780; ups -112,906 | Z35: 300 Mbps at 600 > 500 Mbps at 344 | AA35: OUTSIDE_BAND - compared without converting currency
A36: SG-DIA-100-researched | B36: SG | C36: DIA | D36: 100 | E36: Hold | F36: Published on SPTel's promotion page (valid to 31 Dec 2026). No circuit in the set uses it. | G36: Hold | H36: =J36*0.75 -> 234 | I36: =J36*1.25 -> 390 | J36: 312 | K36: SGD | L36: 243.75 | M36: 660 | N36: =IF(OR(L36="",M36=""),"",L36/M36) -> 0.36931818 | O36: SEED | P36: promotional | Q36: DIA 100 Mbps MRC — Singapore (SPTel enterprise tariff) | R36: SPTel; COMPANY_PUBLISHED/SNIPPET_ONLY | S36: Enterprise Internet 100Mbps $312/mth (on 24-month contract) | T36: https://sptel.com/promotion/business-broadband-singapore/ | U36: 2026 | V36: dbs | W36: 0 | X36: 0 | Z36: no | AA36: OUTSIDE_BAND - compared without converting currency
A37: US-BROADBAND_PON-300-researched | B37: US | C37: BROADBAND_PON | D37: 300 | E37: Hold | F37: AT&T Business Fiber 300, inside AT&T's footprint only. At $70 it is below the national median for 100 Mbps, and would price every US PON circuit up to 300 Mbps at it. | G37: Hold | H37: =J37*0.75 -> 52.5 | I37: =J37*1.25 -> 87.5 | J37: 70 | K37: USD | L37: 70 | N37: =IF(OR(L37="",M37=""),"",L37/M37) | O37: none - new tier | P37: single carrier | Q37: BROADBAND_PON 300 Mbps MRC – US (AT&T Business Fiber published rate) | R37: business.org (AT&T Business Internet Review 2026); AGGREGATOR/SNIPPET_ONLY | S37: Business Fiber 300: $70.00/mo | T37: https://www.business.org/services/internet/att-business-internet-review/ | U37: 2026 | V37: simmons-bank | W37: -153835.98 | X37: 243 | Y37: simmons-bank -60,165; basf -21,803; siemens -18,573 | Z37: 250 Mbps at 114 > 300 Mbps at 70 | AA37: NO_BENCHMARK_AT_BANDWIDTH
A38: ZA-DIA-100-researched | B38: ZA | C38: DIA | D38: 100 | E38: Hold | F38: MWCom 'from around R8,000'; the same research gives R8,000-25,000 depending on distance and capacity. | G38: Hold | H38: =J38*0.75 -> 6000 | I38: =J38*1.25 -> 10000 | J38: 8000 | K38: ZAR | L38: 444.44 | N38: =IF(OR(L38="",M38=""),"",L38/M38) | O38: none - new tier | P38: business retail floor | Q38: DIA 100 Mbps MRC ZA (leased line / dedicated fibre) | R38: mwcom.co.za; COMPANY_PUBLISHED/SNIPPET_ONLY | S38: Leased lines start from around R8,000/mo for 100 Mbps symmetric. | T38: https://www.mwcom.co.za/business-internet-south-africa | U38: 2026 | V38: anglo-american | W38: -16474.243 | X38: 1 | Y38: anglo-american -16,474 | Z38: no | AA38: NO_BENCHMARK_AT_BANDWIDTH - compared without converting currency
A39: AU-DIA-1000-researched | B39: AU | C39: DIA | D39: 1000 | E39: Reject | F39: An on-net data-centre DIA price (Nexthop), not site access. The same research cites A$2,500-8,000 for enterprise dedicated fibre. | G39: Reject | H39: =J39*0.75 -> 374.25 | I39: =J39*1.25 -> 623.75 | J39: 499 | K39: AUD | L39: 337.16 | M39: 1750 | N39: =IF(OR(L39="",M39=""),"",L39/M39) -> 0.19266286 | O39: SEED | P39: datacentre on net | Q39: Nexthop Datacentre DIA — 1 Gbps | R39: Nexthop; COMPANY_PUBLISHED/FULL_PAGE | S39: 1 Gbps datacentre DIA: A$499/month on a 24-month term; on-net. | T39: https://www.nexthop.com.au/dedicated-internet-access/ | U39: 2026-10 | V39: woolworths | W39: -416627.12 | X39: 30 | Y39: woolworths -416,627 | Z39: 500 Mbps at 1610 > 1000 Mbps at 337 | AA39: OUTSIDE_BAND - compared without converting currency
A40: DE-BROADBAND_PON-75-researched | B40: DE | C40: BROADBAND_PON | D40: 75 | E40: Reject | F40: A wholesale bitstream price cap for subsidised networks (BMDV L2-BSA). A business pays the retail price on top of it. | G40: Reject | H40: =J40*0.75 -> 14.415 | I40: =J40*1.25 -> 24.025 | J40: 19.22 | K40: EUR | L40: 22.06 | N40: =IF(OR(L40="",M40=""),"",L40/M40) | O40: none - new tier | P40: wholesale | Q40: DE BROADBAND_PON wholesale bitstream L2-BSA 50-99 Mbps MRC (regulatory price cap) | R40: BMDV / Bundesnetzagentur (German Federal Ministry for Digital Affairs); REGULATOR/SNIPPET_ONLY | S40: 50 – 99 Mbit/s … L2-BSA Überlassungsentgelt … 19,22 € | T40: https://www.bmv.de/SharedDocs/DE/Anlage/DG/vorleistungspreise.pdf?__blob=publicationFile | U40: 2024-12 | V40: fresenius | W40: 0 | X40: 0 | Z40: 50 Mbps at 64 > 75 Mbps at 22 | AA40: NO_BENCHMARK_AT_BANDWIDTH - compared without converting currency
...

Sheet Sets
A1: Country | B1: Product | C1: Researched prices | D1: Recommended for approval | E1: Effect of the recommended set, EUR/yr | F1: Effect if every researched price here is approved, EUR/yr | G1: Largest effects of the recommended set
A2: AU | B2: BROADBAND_HFC | C2: 2 | D2: 250 Mbps, 2000 Mbps | E2: -1000837.4 | F2: -1000837.4 | G2: woolworths -1,000,837
A3: AU | B3: BROADBAND_PON | C3: 1 | D3: 250 Mbps | E3: 0 | F3: 0
A4: AU | B4: DIA | C4: 2 | D4: none | E4: 0 | F4: -459004.96
A5: AU | B5: ETHERNET | C5: 3 | D5: 250 Mbps, 500 Mbps, 1000 Mbps | E5: -357787.61 | F5: -357787.61 | G5: rio-tinto -304,560; woolworths -53,228
A6: BE | B6: BROADBAND_PON | C6: 2 | D6: 150 Mbps | E6: 0 | F6: 0
A7: DE | B7: BROADBAND_PON | C7: 4 | D7: none | E7: 0 | F7: -131200.1
A8: ES | B8: DIA | C8: 3 | D8: none | E8: 0 | F8: -19766168
A9: FR | B9: BROADBAND_PON | C9: 1 | D9: none | E9: 0 | F9: -723966.33
A10: FR | B10: DIA | C10: 1 | D10: 1000 Mbps | E10: -106959.98 | F10: -106959.98 | G10: bnp-paribas -29,777; siemens -26,800; capgemini -14,889
A11: GB | B11: BROADBAND_HFC | C11: 7 | D11: 200 Mbps, 400 Mbps, 600 Mbps, 1000 Mbps, 2000 Mbps | E11: -6205842.7 | F11: -6406768.8 | G11: tesco -2,729,944; boots -1,535,239; mcdonalds -1,526,396
A12: GB | B12: BROADBAND_PON | C12: 2 | D12: 100 Mbps | E12: -742283.22 | F12: -770672.24 | G12: iberdrola -243,421; network-rail -216,375; nhs-england -161,315
A13: GB | B13: DIA | C13: 5 | D13: none | E13: 0 | F13: -5403847.3
A14: GB | B14: ETHERNET | C14: 3 | D14: none | E14: 0 | F14: -3267660.9
A15: GB | B15: MPLS | C15: 1 | D15: none | E15: 0 | F15: 0
A16: IE | B16: BROADBAND_PON | C16: 1 | D16: none | E16: 0 | F16: -3152.9356
A17: IT | B17: ETHERNET | C17: 1 | D17: none | E17: 0 | F17: 0
A18: NL | B18: BROADBAND_PON | C18: 1 | D18: none | E18: 0 | F18: -2369.8429
A19: NL | B19: DIA | C19: 1 | D19: 200 Mbps | E19: 0 | F19: 0
A20: NZ | B20: BROADBAND_PON | C20: 1 | D20: none | E20: 0 | F20: 0
A21: SG | B21: BROADBAND_PON | C21: 2 | D21: 500 Mbps, 1000 Mbps | E21: -2520.0814 | F21: -2520.0814 | G21: dbs -2,199; novartis -321
A22: SG | B22: DIA | C22: 2 | D22: 10000 Mbps | E22: 0 | F22: 0
A23: US | B23: BROADBAND_HFC | C23: 3 | D23: 100 Mbps, 500 Mbps, 1000 Mbps | E23: -17460896 | F23: -17460896 | G23: mcdonalds -14,602,237; ahold-delhaize -1,098,548; ups -865,097
A24: US | B24: BROADBAND_PON | C24: 3 | D24: 100 Mbps, 500 Mbps | E24: 212933.99 | F24: 137060.38 | G24: simmons-bank -20,511; basf -13,372; siemens -11,391
A25: US | B25: DIA | C25: 3 | D25: 100 Mbps, 1000 Mbps, 10000 Mbps | E25: -912496.42 | F25: -912496.42 | G25: simmons-bank -537,948; siemens -314,464; nestle -84,483
A26: US | B26: ETHERNET | C26: 2 | D26: 10000 Mbps | E26: -32322.017 | F26: -32322.017 | G26: shell -32,322
A27: US | B27: MPLS | C27: 1 | D27: 1000 Mbps | E27: 0 | F27: 0
A28: ZA | B28: DIA | C28: 1 | D28: none | E28: 0 | F28: -16474.243
A29: Total | E29: =SUM(E2:E28) -> -26609012 | F29: =SUM(F2:F28) -> -56688045

Sheet By company
A1: Company | B1: Baseline, EUR/yr | C1: Effect of the recommendation, EUR/yr | D1: Change | E1: Effect if every researched price is approved, EUR/yr | F1: Change
A2: mcdonalds | B2: 81967734 | C2: -16128633 | D2: =IF(B2=0,"",C2/B2) -> -0.19676807 | E2: -16135442 | F2: =IF(B2=0,"",E2/B2) -> -0.19685114
A3: tesco | B3: 21814060 | C3: -2729944.1 | D3: =IF(B3=0,"",C3/B3) -> -0.12514608 | E3: -2938988 | F3: =IF(B3=0,"",E3/B3) -> -0.13472907
A4: boots | B4: 11079391 | C4: -1535238.9 | D4: =IF(B4=0,"",C4/B4) -> -0.13856708 | E4: -1585318.4 | F4: =IF(B4=0,"",E4/B4) -> -0.14308715
A5: ahold-delhaize | B5: 28128304 | C5: -1094627.7 | D5: =IF(B5=0,"",C5/B5) -> -0.038915526 | E5: -1094627.7 | F5: =IF(B5=0,"",E5/B5) -> -0.038915526
A6: woolworths | B6: 6323454.1 | C6: -1054065.4 | D6: =IF(B6=0,"",C6/B6) -> -0.16669139 | E6: -1513070.3 | F6: =IF(B6=0,"",E6/B6) -> -0.23927909
A7: ups | B7: 22704990 | C7: -884341.34 | D7: =IF(B7=0,"",C7/B7) -> -0.038949206 | E7: -997247.15 | F7: =IF(B7=0,"",E7/B7) -> -0.043921937
A8: victorias-secret | B8: 4699559.1 | C8: -852215.95 | D8: =IF(B8=0,"",C8/B8) -> -0.18133955 | E8: -852215.95 | F8: =IF(B8=0,"",E8/B8) -> -0.18133955
A9: simmons-bank | B9: 4493834.2 | C9: -558458.55 | D9: =IF(B9=0,"",C9/B9) -> -0.12427217 | E9: -598112.66 | F9: =IF(B9=0,"",E9/B9) -> -0.13309629
A10: siemens | B10: 13615381 | C10: -352654.44 | D10: =IF(B10=0,"",C10/B10) -> -0.02590118 | E10: -676067.91 | F10: =IF(B10=0,"",E10/B10) -> -0.049654718
A11: deutsche-post-dhl | B11: 19497183 | C11: -349440.29 | D11: =IF(B11=0,"",C11/B11) -> -0.017922604 | E11: -2268262.1 | F11: =IF(B11=0,"",E11/B11) -> -0.11633794
A12: rio-tinto | B12: 1634821.5 | C12: -304559.64 | D12: =IF(B12=0,"",C12/B12) -> -0.18629535 | E12: -344257.21 | F12: =IF(B12=0,"",E12/B12) -> -0.21057786
A13: iberdrola | B13: 13002328 | C13: -243421.43 | D13: =IF(B13=0,"",C13/B13) -> -0.018721373 | E13: -482074.1 | F13: =IF(B13=0,"",E13/B13) -> -0.037075984
... A45: fresenius | B45: 36794481 | C45: 635912.58 | D45: =IF(B45=0,"",C45/B45) -> 0.017282825 | E45: -4175490.7 | F45: =IF(B45=0,"",E45/B45) -> -0.11348144
A46: Companies affected | B46: =SUM(B2:B45) -> 5.503231e+08 | C46: =SUM(C2:C45) -> -26609012 | D46: =C46/B46 -> -0.048351618 | E46: =SUM(E2:E45) -> -56688045 | F46: =E46/B46 -> -0.10300866
